Workbook

Sheet Lists
A1: Bloom Level | B1: Short meaning | D1: ABET PO | E1: Short descriptor | G1: EUR-ACE PO | H1: Learning area | J1: MÜDEK PO | K1: Program Outcome | M1: ALO Mapping Options | O1: Inactive list | Q1: Notes / Sources | R1: Reference | S1: Question IDs
A2: Remember | B2: Recall or recognize information | D2: PO-1 | E2: Complex engineering problem solving | G2: PO-1 | H2: Knowledge and Understanding | J2: PÇ-1.1 | K2: Adequate knowledge of mathematics and natural sciences. | M2: ALO-1 | Q2: EUR-ACE numbering | R2: PO-1...PO-8 are internal workbook labels for the eight EAFSG learning areas. | S2: Q1
A3: Understand | B3: Explain, interpret, summarize, classify, or compare | D3: PO-2 | E3: Engineering design under specified needs and contextual constraints | G3: PO-2 | H3: Engineering Analysis | J3: PÇ-1.2 | K3: Adequate knowledge of subjects specific to Environmental Engineering. | M3: ALO-2 | Q3: ABET source | R3: https://www.abet.org/accreditation/accreditation-criteria/criteria-for-accrediting-engineering-programs-2026-2027/ | S3: Q2
A4: Apply | B4: Use a known procedure or method in a given situation | D4: PO-3 | E4: Effective communication | G4: PO-3 | H4: Engineering Design | J4: PÇ-1.3 | K4: Ability to apply theoretical and practical knowledge in these areas to complex engineering problems. | M4: ALO-3 | Q4: EUR-ACE source | R4: https://www.enaee.eu/wp-content/uploads/2022/03/EAFSG-04112021-English-1-1.pdf | S4: Q3
A5: Analyze | B5: Break information into parts and determine relationships | D5: PO-4 | E5: Ethical/professional responsibility and informed judgment | G5: PO-4 | H5: Investigations | J5: PÇ-2.1 | K5: Ability to identify, define, formulate, and solve complex engineering problems. | M5: ALO-4 | Q5: MÜDEK / departmental PÇ | R5: PÇ list supplied for the Environmental Engineering program; version not specified. | S5: Q4
A6: Evaluate | B6: Make a judgment using criteria or standards | D6: PO-5 | E6: Effective teamwork | G6: PO-5 | H6: Engineering Practice | J6: PÇ-2.2 | K6: Ability to select and apply appropriate analysis and modeling methods for this purpose. | M6: ALO-5 | Q6: ALO rule | R6: Define ALOs consecutively from ALO-1. Up to five ALOs are supported. | S6: Q5
A7: Create | B7: Generate, plan, or produce a new solution or product | D7: PO-6 | E7: Experimentation, data interpretation, and engineering judgment | G7: PO-6 | H7: Making Judgements | J7: PÇ-3.1 | K7: Ability to design a complex system, process, device, or product to meet specified requirements under realistic constraints and conditions.
D8: PO-7 | E8: Acquire and apply new knowledge | G8: PO-7 | H8: Communication and Team-working | J8: PÇ-3.2 | K8: Ability to apply modern design methods for this purpose.
G9: PO-8 | H9: Lifelong Learning | J9: PÇ-4.1 | K9: Ability to develop, select, and use modern techniques and tools required for the analysis and solution of complex problems encountered in engineering practice.
J10: PÇ-4.2 | K10: Ability to use information technologies effectively.
J11: PÇ-5.1 | K11: Ability to design experiments for the investigation of complex engineering problems or discipline-specific research topics.
J12: PÇ-5.2 | K12: Ability to conduct experiments for the investigation of complex engineering problems or discipline-specific research topics.
J13: PÇ-5.3 | K13: Ability to collect data for the investigation of complex engineering problems or discipline-specific research topics.
J14: PÇ-5.4 | K14: Ability to analyze and interpret experimental results for the investigation of complex engineering problems or discipline-specific research topics.
J15: PÇ-6.1 | K15: Ability to work individually within the discipline.
J16: PÇ-6.2 | K16: Ability to work effectively in disciplinary teams.
J17: PÇ-6.3 | K17: Ability to work effectively in multidisciplinary teams.
J18: PÇ-7.1 | K18: Ability to communicate effectively in oral and written form and to make presentations.
J19: PÇ-7.2 | K19: Knowledge of at least one foreign language.
J20: PÇ-7.3 | K20: Ability to write effective reports and understand written reports.
J21: PÇ-7.4 | K21: Ability to prepare design and production reports.
... J31: PÇ-11.2 | K31: Awareness of the legal consequences of engineering solutions.

Sheet Activity Info
A1: WAIT… SLUDGE HAS AN AGE?
A2: Activity topic | G2: Sludge retention time control and waste solids production in an activated-sludge process
A4: Activity ID | G4: CB-003
A5: Activity version | G5: 1.0
A6: Publication date | G6: 14 August 2026
A7: CEMBench ASM version | G7: at least 1.0.0
A8: Reference activity | G8: CB-002. How long is long enough?
A9: Reference video | G9: https://youtu.be/1zKYDCrlW3A
A10: Contributor | B10: name | G10: Neslihan Manav Demir
B11: email | G11: nmanav@yildiz.edu.tr
B12: institution | G12: Yıldız Technical University
B13: department | G13: Department of Environmental Engineering
A15: Purpose and Scope | G15: This activity introduces sludge retention time (SRT) as an operating parameter of the activated-sludge process. Students use five different waste activated sludge (WAS) flows while keeping the reactor dimensions, influent conditions, secondary clarifier, RAS flow, and all other model settings constant. WAS flow is varied to investigate how SRT can be controlled in an operating system. Students calculate SRT from steady-state CEMBench ASM results and examine the relationship between WAS flow and SRT. They then use the same results to calculate waste solids production and specific waste solids production and analyze their relationship with SRT.
A17: Target students | G17: Undergraduate, beginner level
A18: Timing | G18: After CB-002 and after introducing the concepts of waste activated sludge and sludge retention time.
A19: Mode of use | G19: In-class activity or homework
A20: Guidance level | G20: Guided
A21: ETC | G21: Approximately 30-40 minutes, excluding any instructor-led discussion
A22: Highest Bloom | B22: Level | G22: =IF(COUNTIF($Z$36:$Z$40,"Create")>0,"Create",IF(COUNTIF($Z$36:$Z$40,"Evaluate")>0,"Evaluate",IF(COUNTIF($Z$36:$Z$40,"Analyze")>0,"Analyze",IF(COUNTIF($Z$36:$Z$40,"Apply")>0,"Apply",IF(COUNTIF($Z$36:$Z$40,"Understand")>0,"Understand",IF(COUNTIF($Z$36:$Z$40,"Remember")>0,"Remember","")))))) -> Analyze
B23: Justification | G23: In Q1, the student applies the SRT calculation using steady-state simulation results obtained for different WAS flowrates and determines how WAS flow can be used to control SRT. In Q2, the student reuses the simulation results to calculate waste solids production and specific waste solids production and analyzes their relationship with SRT.
A25: Prerequisites | G25: Basic concepts: activated-sludge treatment, secondary clarification, RAS, WAS, hydraulic retention time, sludge retention time, MLSS, and solids mass flow. Basic CEMBench ASM skills: creating a project from a template, drawing an activated-sludge topology, defining characterizations and unit properties, defining known-flow links, running Project Check, performing steady-state simulations, and reading steady-state results. Completion of CB-002 is recommended.
A27: Activity Learning Outcomes (ALOs)
A28: ALO-1 | G28: The student will be able to calculate sludge retention time and explain how waste activated sludge flow is used to control SRT.
A29: ALO-2 | G29: The student will be able to relate sludge retention time to waste solids production and specific waste solids production.
A30: ALO-3
A31: ALO-4
A32: ALO-5
A34: Program Outcomes (POs) and Bloom Mapping
A35: Question ID | D35: ALOs | H35: ABET POs | N35: EUR-ACE POs | T35: MÜDEK POs | Z35: Bloom level
A36: Q1 | D36: ALO-1 | H36: PO-6 | N36: PO-2 | T36: PÇ-1.2 | Z36: Understand
A37: Q2 | D37: ALO-2 | H37: PO-6 | N37: PO-2 | T37: PÇ-2.2 | Z37: Analyze
A42: Recommended Implementation (In-Class)
A43: Preparation | G43: Review the distinction between hydraulic retention time and sludge retention time and the roles of RAS and WAS in an activated-sludge system. The 6-hour HRT configuration used in CB-002 may be briefly revisited.
A44: Opening | G44: Ask: “Once an activated-sludge plant has been built, how can the operator change how long the solids remain in the system without changing the reactor volume?” Collect brief predictions before the simulations.
A45: Guidance | G45: Students build the CB-002 topology using the fixed 6-hour HRT configuration. Demonstrate the first WAS-flow case if necessary. Students then change only the WAS flow, obtain the required steady-state MLSS concentrations, calculate SRT, and complete the Q1 analysis. Q2 is completed entirely from the results obtained in Q1 and requires no additional CEMBench ASM simulations.
A46: Discussion | G46: Discuss WAS flow as an operational control variable for SRT and use the Q2 results to discuss how changing solids retention affects the mass of solids that must be removed and handled.
A48: Recommended Implementation (Homework)
A49: Preparation | G49: Provide the activity workbook and the Introductory S-X Model template. Students should preferably have completed CB-002 and should be familiar with steady-state simulation, RAS, WAS, and reading MLSS results in CEMBench ASM.
A50: Assignment Release | G50: Students complete five steady-state simulations independently using the prescribed topology and operating conditions. Only the WAS flow is changed between simulations. Q2 is completed using the results generated in Q1 without additional simulations.
A51: Support and Resources | G51: Provide the CEMBench ASM user manual and reference video, if available. Clarify software-operation questions when necessary, but do not provide the expected WAS-flow–SRT relationship or the expected relationship between SRT and waste solids production.
...

Sheet Q1
A1: ="ACTIVITY " & 'Activity Info'!G4 & " — QUESTION 1" -> ACTIVITY CB-003 — QUESTION 1
A3: ETC | G3: 20-25 minutes
A4: ALO | G4: =IF('Activity Info'!D36<>"",VLOOKUP('Activity Info'!D36,'Activity Info'!A28:G32,7),"") -> The student will be able to calculate sludge retention time and explain how waste activated sludge flow is used to control SRT.
A5: ABET PO | G5: =IF('Activity Info'!H36<>"",'Activity Info'!H36,"") -> PO-6
A6: EUR-ACE PO | G6: =IF('Activity Info'!N36<>"",'Activity Info'!N36,"") -> PO-2
A7: MÜDEK PO | G7: =IF('Activity Info'!T36<>"",'Activity Info'!T36,"") -> PÇ-1.2
A8: Bloom level | G8: =IF('Activity Info'!Z36<>"",'Activity Info'!Z36,"") -> Understand
A10: Question | G10: Using the prescribed activated-sludge topology and operating conditions below, investigate how waste activated sludge (WAS) flow affects sludge retention time (SRT). Perform a separate steady-state simulation for each specified WAS flow rate. For every case, record the MLSS concentration in the aerated reactor and the MLSS concentration entering the Sludge Unit, and calculate the corresponding SRT. Plot SRT against WAS flow and explain how WAS flow can be used to control SRT in an activated-sludge system.
A12: Topology and CEMBench ASM Setup
A13: Model template | G13: Introductory S-X Model.cbt
A14: Influent | B14: Flow | G14: 100 m3/h
B15: Pattern | G15: Default Multiplicative
B16: Characterizat'n | G16: SO = 0 mg/L, SS = 250 mg/L; XH = 0 mg/L
A17: Reactor | B17: Area | G17: 120 m2
B18: Depth | G18: 5 m
B19: Aeration | G19: Constant DO @ 2 mg/L
B20: Initials | G20: SO = 0 mg/L, SS = 5 mg/L; XH = 1000 mg/L
A21: Clarifier | B21: Area | G21: 200 m2
B22: Depth | G22: 3 m
B23: Inlet layer | G23: 5
A24: RAS flow | G24: 100 m3/h
A25: WAS flow | G25: 0.5, 1.0, 1.5, 2.0, 2.5 m3/h
A26: Simulat'n settings | G26: Steady-state simulation
A27: Topology figure | G27: Insert CEMBench ASM topology screenshot here
A29: Instructions | G29: 1. Create a new CEMBench ASM project using Introductory S-X Model.cbt. 2. Build the prescribed topology, including the secondary clarifier, RAS line, and WAS line. 3. Define the influent flow, pattern, and characterization given above. 4. Define the aerated reactor with a surface area of 120 m² and a depth of 5 m. Confirm that CEMBench ASM calculates a reactor volume of 600 m³. 5. Define the reactor initial characterization and set constant DO to 2 mg/L. 6. Define the secondary clarifier and set the RAS flow to 100 m³/h. 7. Start with a WAS flow of 0.5 m³/h. 8. Run Project Check and perform a steady-state simulation. 9. Record the steady-state MLSS concentration in the aerated reactor and the MLSS concentration entering the Sludge Unit. 10. Calculate the corresponding SRT. 11. Repeat the steady-state simulation for WAS flows of 1.0, 1.5, 2.0, 2.5 m³/h. Change only the WAS flow and keep all other project settings unchanged. 12. Record the required MLSS concentrations and calculate SRT for every case. 13. Plot SRT (d) against WAS flow (m³/h). 14. Explain the relationship between WAS flow and SRT and describe how an operator can use WAS flow to control SRT.
A31: Requir'd submiss'n | G31: 1. Complete written answer to Q1, including the completed results table and WAS flow–SRT chart. 2. CEMBench ASM project file (CBM) for the final simulation case, named Q1.cbm.

Sheet Q2
A1: ="ACTIVITY " & 'Activity Info'!G4 & " — QUESTION 2" -> ACTIVITY CB-003 — QUESTION 2
A3: ETC | G3: 10-15 minutes
A4: ALO | G4: =IF('Activity Info'!D37<>"",VLOOKUP('Activity Info'!D37,'Activity Info'!A28:G32,7),"") -> The student will be able to relate sludge retention time to waste solids production and specific waste solids production.
A5: ABET PO | G5: =IF('Activity Info'!H37<>"",'Activity Info'!H37,"") -> PO-6
A6: EUR-ACE PO | G6: =IF('Activity Info'!N37<>"",'Activity Info'!N37,"") -> PO-2
A7: MÜDEK PO | G7: =IF('Activity Info'!T37<>"",'Activity Info'!T37,"") -> PÇ-2.2
A8: Bloom level | G8: =IF('Activity Info'!Z37<>"",'Activity Info'!Z37,"") -> Analyze
A10: Question | G10: Using the results obtained in Q1, determine the amount of waste solids discharged from the system at each WAS flow rate and calculate the specific waste solids production per unit volume of influent wastewater. Use the corresponding SRT values obtained in Q1 to examine the relationship between SRT and specific waste solids production. No additional CEMBench ASM simulations are required.
A12: Topology and CEMBench ASM Setup
A13: Model template
A14: Influent | B14: Flow
B15: Pattern
B16: Characterizat'n
A17: Reactor | B17: Area
B18: Depth
B19: Aeration
B20: Initials
A21: Clarifier | B21: Area
B22: Depth
B23: Inlet layer
A24: RAS flow
A25: Simulat'n settings | G25: No additional simulation is required. Use the steady-state results obtained in Q1.
A26: Topology figure | G26: Insert CEMBench ASM topology screenshot here
A28: Instructions | G28: 1. Use the five WAS-flow cases completed in Q1. Do not perform any additional CEMBench ASM simulations. 2. Transfer the WAS flow, SRT, and Sludge Unit influent MLSS concentration for each case from your Q1 results. 3. For every case, calculate the waste solids production in kg/h using the WAS flow and the MLSS concentration entering the Sludge Unit. 4. Calculate the specific waste solids production in kg solids/m³ influent using the influent flow of 100 m³/h. 5. Complete the results table for all five cases. 6. Plot specific waste solids production against SRT. 7. Examine the resulting relationship and explain how waste solids production changes with SRT. 8. Explain the operational implication of changing SRT in terms of the amount of solids that must be removed from the system.
A30: Requir'd submiss'n | G30: 1. Complete written answer to Q2, including the completed results table and specific waste solids production–SRT chart.

Sheet Q3
A1: ="ACTIVITY " & 'Activity Info'!G4 & " — QUESTION 3" -> ACTIVITY CB-003 — QUESTION 3
A3: ETC
A4: ALO | G4: =IF('Activity Info'!D38<>"",VLOOKUP('Activity Info'!D38,'Activity Info'!A28:G32,7),"")
A5: ABET PO | G5: =IF('Activity Info'!H38<>"",'Activity Info'!H38,"")
A6: EUR-ACE PO | G6: =IF('Activity Info'!N38<>"",'Activity Info'!N38,"")
A7: MÜDEK PO | G7: =IF('Activity Info'!T38<>"",'Activity Info'!T38,"")
A8: Bloom level | G8: =IF('Activity Info'!Z38<>"",'Activity Info'!Z38,"")
A10: Question
A12: Topology and CEMBench ASM Setup
A13: Model template
A14: Influent | B14: Flow
B15: Pattern
B16: Characterizat'n
A17: Reactor | B17: Area
B18: Depth
B19: Aeration
B20: Initials
A21: Simulat'n settings
A22: Topology figure | G22: Insert CEMBench ASM topology screenshot here
A24: Instructions
A26: Requir'd submiss'n

Sheet Q4
A1: ="ACTIVITY " & 'Activity Info'!G4 & " — QUESTION 4" -> ACTIVITY CB-003 — QUESTION 4
A3: ETC
A4: ALO
A5: ABET PO
A6: EUR-ACE PO
A7: MÜDEK PO
A8: Bloom level
A10: Question
A12: Topology and CEMBench ASM Setup
A13: Model template
A14: Influent | B14: Flow
B15: Pattern
B16: Characterizat'n
A17: Reactor | B17: Area
B18: Depth
B19: Aeration
B20: Initials
A21: Simulat'n settings
A22: Topology figure | G22: Insert CEMBench ASM topology screenshot here
A24: Instructions
A26: Requir'd submiss'n

Sheet Q5
A1: ="ACTIVITY " & 'Activity Info'!G4 & " — QUESTION 5" -> ACTIVITY CB-003 — QUESTION 5
A3: ETC
A4: ALO
A5: ABET PO
A6: EUR-ACE PO
A7: MÜDEK PO
A8: Bloom level
A10: Question
A12: Topology and CEMBench ASM Setup
A13: Model template
A14: Influent | B14: Flow
B15: Pattern
B16: Characterizat'n
A17: Reactor | B17: Area
B18: Depth
B19: Aeration
B20: Initials
A21: Simulat'n settings
A22: Topology figure | G22: Insert CEMBench ASM topology screenshot here
A24: Instructions
A26: Requir'd submiss'n
